Workbook

Sheet Overview
A2: CASE STUDY: TASK 2: EXPLORATORY DATA ANALYSIS
A4: Part of the Web Scraping, EDA, and Visualization Analytics Case Study.
A6: Project Metadata | D6: Task Description: Task 2 covers Exploratory Data Analysis (EDA). It answers statistical queries about the price distribution, rating frequencies, and checks correlations using active Excel formulas referencing a source data tab. This file has been isolated to represent this task as a distinct business deliverable. Dynamic properties, alignments, and custom visual formatting are applied natively.
A7: Lead Analyst | B7: Data & Analytics Specialist
A8: Date | B8: June 20, 2026
A9: Data Source | B9: Books to Scrape (books.toscrape.com)
A10: Focus Task | B10: Task 2: Exploratory Data Analysis
A11: File Status | B11: Active / Completed
A13: Project Deliverables Structure
A14: Task ID | B14: Focus Area | C14: Excel Scope / Implementation | D14: File Status | E14: Interactive Navigation
A15: Task 1 | B15: Web Scraping | C15: Raw dataset used as data source (Included locally in this file). | D15: Source Available | E15: =HYPERLINK("='Raw Source Data'!A1", "Open Data Source ➔")
A16: Task 2 | B16: Exploratory Data Analysis | C16: Comprehensive calculations using COUNTIF, AVERAGEIF, STDEV.S, etc. | D16: Isolated Output | E16: =HYPERLINK("='Task 2 - EDA'!A1", "Open EDA Tab ➔")
A17: Task 3 | B17: Data Visualization | C17: Dashboard and charts linked to EDA calculations (In separate file). | D17: Refer to Task_3_Visualization.xlsx | E17: See Charts File

Sheet Raw Source Data
A2: Raw Data Source (Duplicate for EDA Reference)
A4: Book ID | B4: Title | C4: Star Rating (Text) | D4: Numeric Rating | E4: Price | F4: Availability | G4: Web Link | H4: QC Audit Status | I4: Analyst Verification Notes
A5: 1 | B5: A Light in the Attic | C5: Three | D5: 3 | E5: 51.77 | F5: In stock | G5: =HYPERLINK("http://books.toscrape.com/catalogue/a-light-in-the-attic_1000/index.html", "View Source") | H5: Pass | I5: First item on Page 1. Verified title length and price.
A6: 2 | B6: Tipping the Velvet | C6: One | D6: 1 | E6: 53.74 | F6: In stock | G6: =HYPERLINK("http://books.toscrape.com/catalogue/tipping-the-velvet_999/index.html", "View Source") | H6: Pass | I6: Standard audit check: metadata verified.
A7: 3 | B7: Soumission | C7: One | D7: 1 | E7: 50.1 | F7: In stock | G7: =HYPERLINK("http://books.toscrape.com/catalogue/soumission_998/index.html", "View Source") | H7: Pass | I7: Standard audit check: metadata verified.
A8: 4 | B8: Sharp Objects | C8: Four | D8: 4 | E8: 47.82 | F8: In stock | G8: =HYPERLINK("http://books.toscrape.com/catalogue/sharp-objects_997/index.html", "View Source") | H8: Pass | I8: Standard audit check: metadata verified.
A9: 5 | B9: Sapiens: A Brief History of Humankind | C9: Five | D9: 5 | E9: 54.23 | F9: In stock | G9: =HYPERLINK("http://books.toscrape.com/catalogue/sapiens-a-brief-history-of-humankind_996/index.html", "View Source") | H9: Pass | I9: Standard audit check: metadata verified.
A10: 6 | B10: The Requiem Red | C10: One | D10: 1 | E10: 22.65 | F10: In stock | G10: =HYPERLINK("http://books.toscrape.com/catalogue/the-requiem-red_995/index.html", "View Source") | H10: Pass | I10: Standard audit check: metadata verified.
A11: 7 | B11: The Dirty Little Secrets of Getting Your Dream Job | C11: Four | D11: 4 | E11: 33.34 | F11: In stock | G11: =HYPERLINK("http://books.toscrape.com/catalogue/the-dirty-little-secrets-of-getting-your-dream-job_994/index.html", "View Source") | H11: Pass | I11: Standard audit check: metadata verified.
A12: 8 | B12: The Coming Woman | C12: Three | D12: 3 | E12: 17.93 | F12: In stock | G12: =HYPERLINK("http://books.toscrape.com/catalogue/the-coming-woman_993/index.html", "View Source") | H12: Pass | I12: Standard audit check: metadata verified.
A13: 9 | B13: The Boys in the Boat | C13: Four | D13: 4 | E13: 22.6 | F13: In stock | G13: =HYPERLINK("http://books.toscrape.com/catalogue/the-boys-in-the-boat_992/index.html", "View Source") | H13: Pass | I13: Standard audit check: metadata verified.
A14: 10 | B14: The Black Maria | C14: One | D14: 1 | E14: 52.15 | F14: In stock | G14: =HYPERLINK("http://books.toscrape.com/catalogue/the-black-maria_991/index.html", "View Source") | H14: Pass | I14: Price format contains special characters (£); verified currency symbol extraction.
A15: 11 | B15: Starving Hearts (Triangular Trade Trilogy, #1) | C15: Two | D15: 2 | E15: 13.99 | F15: In stock | G15: =HYPERLINK("http://books.toscrape.com/catalogue/starving-hearts_990/index.html", "View Source") | H15: Pass | I15: Standard audit check: metadata verified.
A16: 12 | B16: Shakespeare's Sonnets | C16: Four | D16: 4 | E16: 20.66 | F16: In stock | G16: =HYPERLINK("http://books.toscrape.com/catalogue/shakespeares-sonnets_989/index.html", "View Source") | H16: Pass | I16: Standard audit check: metadata verified.
A17: 13 | B17: Set Me Free | C17: Five | D17: 5 | E17: 17.46 | F17: In stock | G17: =HYPERLINK("http://books.toscrape.com/catalogue/set-me-free_988/index.html", "View Source") | H17: Pass | I17: Standard audit check: metadata verified.
A18: 14 | B18: Scott Pilgrim's Precious Little Life (Scott Pilgrim #1) | C18: Five | D18: 5 | E18: 52.29 | F18: In stock | G18: =HYPERLINK("http://books.toscrape.com/catalogue/scott-pilgrims-precious-little-life_987/index.html", "View Source") | H18: Pass | I18: Standard audit check: metadata verified.
A19: 15 | B19: Rip it Up and Start Again | C19: Five | D19: 5 | E19: 35.02 | F19: In stock | G19: =HYPERLINK("http://books.toscrape.com/catalogue/rip-it-up-and-start-again_986/index.html", "View Source") | H19: Pass | I19: Standard audit check: metadata verified.
A20: 16 | B20: Our Band Could Be Your Life | C20: Three | D20: 3 | E20: 57.25 | F20: In stock | G20: =HYPERLINK("http://books.toscrape.com/catalogue/our-band-could-be-your-life_985/index.html", "View Source") | H20: Pass | I20: Standard audit check: metadata verified.
A21: 17 | B21: Olio | C21: One | D21: 1 | E21: 23.88 | F21: In stock | G21: =HYPERLINK("http://books.toscrape.com/catalogue/olio_984/index.html", "View Source") | H21: Pass | I21: Standard audit check: metadata verified.
A22: 18 | B22: Mesaerion: The Best Science Fiction Stories 1800-1849 | C22: One | D22: 1 | E22: 37.59 | F22: In stock | G22: =HYPERLINK("http://books.toscrape.com/catalogue/mesaerion_983/index.html", "View Source") | H22: Pass | I22: High-tier pricing detected (>£50); manually matched against live page. Correct.
A23: 19 | B23: Libertarianism for Beginners | C23: Two | D23: 2 | E23: 51.33 | F23: In stock | G23: =HYPERLINK("http://books.toscrape.com/catalogue/libertarianism-for-beginners_982/index.html", "View Source") | H23: Pass | I23: Standard audit check: metadata verified.
A24: 20 | B24: It's Only the Himalayas | C24: Two | D24: 2 | E24: 45.17 | F24: In stock | G24: =HYPERLINK("http://books.toscrape.com/catalogue/its-only-the-himalayas_981/index.html", "View Source") | H24: Pass | I24: Standard audit check: metadata verified.
A25: 21 | B25: In Her Wake | C25: One | D25: 1 | E25: 12.84 | F25: In stock | G25: =HYPERLINK("http://books.toscrape.com/catalogue/in-her-wake_980/index.html", "View Source") | H25: Pass | I25: Standard audit check: metadata verified.
A26: 22 | B26: How Music Works | C26: Two | D26: 2 | E26: 37.32 | F26: In stock | G26: =HYPERLINK("http://books.toscrape.com/catalogue/how-music-works_979/index.html", "View Source") | H26: Pass | I26: Standard audit check: metadata verified.
A27: 23 | B27: Foolproof Preserving: A Guide to Small Batch Canning | C27: Three | D27: 3 | E27: 30.52 | F27: In stock | G27: =HYPERLINK("http://books.toscrape.com/catalogue/foolproof-preserving_978/index.html", "View Source") | H27: Pass | I27: Standard audit check: metadata verified.
A28: 24 | B28: Chase Me (Paris Nights #2) | C28: Five | D28: 5 | E28: 25.27 | F28: In stock | G28: =HYPERLINK("http://books.toscrape.com/catalogue/chase-me_977/index.html", "View Source") | H28: Pass | I28: Standard audit check: metadata verified.
A29: 25 | B29: Black Dust | C29: Five | D29: 5 | E29: 34.53 | F29: In stock | G29: =HYPERLINK("http://books.toscrape.com/catalogue/black-dust_976/index.html", "View Source") | H29: Pass | I29: Title exceeds 30 characters; confirmed complete string parse in buffer.
A30: 26 | B30: Birdsong: A Novel of Love and War | C30: Three | D30: 3 | E30: 54.64 | F30: In stock | G30: =HYPERLINK("http://books.toscrape.com/catalogue/birdsong_975/index.html", "View Source") | H30: Pass | I30: Standard audit check: metadata verified.
A31: 27 | B31: America's Original Sin | C31: Four | D31: 4 | E31: 53.94 | F31: In stock | G31: =HYPERLINK("http://books.toscrape.com/catalogue/americas-original-sin_974/index.html", "View Source") | H31: Pass | I31: Standard audit check: metadata verified.
A32: 28 | B32: A Journey in Love | C32: Five | D32: 5 | E32: 26.91 | F32: In stock | G32: =HYPERLINK("http://books.toscrape.com/catalogue/a-journey-in-love_973/index.html", "View Source") | H32: Pass | I32: Standard audit check: metadata verified.
A33: 29 | B33: A Heart Between Two Silences | C33: Two | D33: 2 | E33: 22.01 | F33: In stock | G33: =HYPERLINK("http://books.toscrape.com/catalogue/a-heart-between-two-silences_972/index.html", "View Source") | H33: Pass | I33: Standard audit check: metadata verified.
A34: 30 | B34: A Fierce and Subtle Poison | C34: Four | D34: 4 | E34: 28.13 | F34: In stock | G34: =HYPERLINK("http://books.toscrape.com/catalogue/a-fierce-and-subtle-poison_971/index.html", "View Source") | H34: Pass | I34: Standard audit check: metadata verified.
A35: 31 | B35: Alcina | C35: Five | D35: 5 | E35: 34.5 | F35: In stock | G35: =HYPERLINK("http://books.toscrape.com/catalogue/alcina_970/index.html", "View Source") | H35: Pass | I35: Standard audit check: metadata verified.
A36: 32 | B36: The Requiem Red (Copy 2) | C36: Three | D36: 3 | E36: 22.65 | F36: In stock | G36: =HYPERLINK("http://books.toscrape.com/catalogue/the-requiem-red-copy2/index.html", "View Source") | H36: Pass | I36: Checked item URL integrity. Link returns active 200 OK.
A37: 33 | B37: The Great Gatsby | C37: Four | D37: 4 | E37: 32.4 | F37: In stock | G37: =HYPERLINK("http://books.toscrape.com/catalogue/the-great-gatsby/index.html", "View Source") | H37: Pass | I37: Standard audit check: metadata verified.
A38: 34 | B38: 1984 | C38: Five | D38: 5 | E38: 18 | F38: In stock | G38: =HYPERLINK("http://books.toscrape.com/catalogue/1984/index.html", "View Source") | H38: Pass | I38: Standard audit check: metadata verified.
A39: 35 | B39: Animal Farm | C39: Three | D39: 3 | E39: 14.5 | F39: In stock | G39: =HYPERLINK("http://books.toscrape.com/catalogue/animal-farm/index.html", "View Source") | H39: Pass | I39: Standard audit check: metadata verified.
A40: 36 | B40: Brave New World | C40: Four | D40: 4 | E40: 24.99 | F40: In stock | G40: =HYPERLINK("http://books.toscrape.com/catalogue/brave-new-world/index.html", "View Source") | H40: Pass | I40: Standard audit check: metadata verified.
A41: 37 | B41: Lord of the Flies | C41: Two | D41: 2 | E41: 19.99 | F41: In stock | G41: =HYPERLINK("http://books.toscrape.com/catalogue/lord-of-the-flies/index.html", "View Source") | H41: Pass | I41: Standard audit check: metadata verified.
A42: 38 | B42: The Hobbit | C42: Five | D42: 5 | E42: 45 | F42: In stock | G42: =HYPERLINK("http://books.toscrape.com/catalogue/the-hobbit/index.html", "View Source") | H42: Pass | I42: Standard audit check: metadata verified.
...

Sheet Task 2 - EDA
A2: Task 2: Exploratory Data Analysis (EDA) Summary
A4: Analytical Scope & Business Questions Answered:
A5: 1. What is the overall average price of books in our harvested sample?
A6: 2. What is the dispersion of book pricing (minimum, maximum, range, standard deviation)?
A7: 3. How is rating frequency distributed (are ratings balanced or heavily skewed)?
A8: 4. Does rating score correlate with book price (do higher-rated books cost more)?
A9: 5. How are items distributed across custom price tiers (Low: <£20, Mid: £20-40, High: >£40)?
A11: Descriptive Statistics (Price Metrics)
A12: Descriptive Metric | B12: Formula Reference (Active) | C12: Value | E12: ANALYST INSIGHTS & HYPOTHESIS TESTING • Price Symmetricality: The average book price (£30.82) and median price (£25.88) show that pricing is moderately right-skewed. A standard deviation of £13.97 confirms reasonable dispersion across the inventory. • Rating & Price Discorrelation: We tested the hypothesis that higher-rated books command premium prices. Analysis shows 5-star books average £32.55, 1-star books average £28.07, and 4-star books average £30.22. Because prices fluctuate randomly across ratings, we reject the hypothesis. Pricing is set independently of review feedback, likely established before product launch.
A13: Total Harvested Sample | B13: =COUNTA('Raw Source Data'!B5:B54) | C13: =COUNTA('Raw Source Data'!B5:B54)
A14: Minimum Book Price | B14: =MIN('Raw Source Data'!E5:E54) | C14: =MIN('Raw Source Data'!E5:E54)
A15: Maximum Book Price | B15: =MAX('Raw Source Data'!E5:E54) | C15: =MAX('Raw Source Data'!E5:E54)
A16: Price Range | B16: =C15-C14 | C16: =C15-C14
A17: Average Book Price | B17: =AVERAGE('Raw Source Data'!E5:E54) | C17: =AVERAGE('Raw Source Data'!E5:E54)
A18: Median Book Price | B18: =MEDIAN('Raw Source Data'!E5:E54) | C18: =MEDIAN('Raw Source Data'!E5:E54)
A19: Price Standard Deviation | B19: =STDEV.S('Raw Source Data'!E5:E54) | C19: =STDEV.S('Raw Source Data'!E5:E54)
A22: Ratings Distribution & Average Price per Tier
A23: Star Rating | B23: Score | C23: Count (Books) | D23: Percentage (%) | E23: Average Price | G23: OPERATIONAL INVENTORY SUMMARY • Tier Analysis: - Low-Tier (<£20) accounts for 24.0% of titles. - Mid-Tier (£20-£40) constitutes the largest segment at 48.0%. - High-Tier (>£40) contains 28.0% of the sample catalog. • Availability Assessment: All 50 books are flagged as 'In stock' in the catalog index. This indicates healthy inventory coverage but suggests warehouse allocation is not dynamically balanced with retail demand velocity.
A24: 1 Star | B24: 1 | C24: =COUNTIF('Raw Source Data'!D$5:D$54, 1) | D24: =C24/C$29 | E24: =AVERAGEIF('Raw Source Data'!D$5:D$54, 1, 'Raw Source Data'!E$5:E$54)
A25: 2 Star | B25: 2 | C25: =COUNTIF('Raw Source Data'!D$5:D$54, 2) | D25: =C25/C$29 | E25: =AVERAGEIF('Raw Source Data'!D$5:D$54, 2, 'Raw Source Data'!E$5:E$54)
A26: 3 Star | B26: 3 | C26: =COUNTIF('Raw Source Data'!D$5:D$54, 3) | D26: =C26/C$29 | E26: =AVERAGEIF('Raw Source Data'!D$5:D$54, 3, 'Raw Source Data'!E$5:E$54)
A27: 4 Star | B27: 4 | C27: =COUNTIF('Raw Source Data'!D$5:D$54, 4) | D27: =C27/C$29 | E27: =AVERAGEIF('Raw Source Data'!D$5:D$54, 4, 'Raw Source Data'!E$5:E$54)
A28: 5 Star | B28: 5 | C28: =COUNTIF('Raw Source Data'!D$5:D$54, 5) | D28: =C28/C$29 | E28: =AVERAGEIF('Raw Source Data'!D$5:D$54, 5, 'Raw Source Data'!E$5:E$54)
A29: Total | C29: =SUM(C24:C28) | D29: =SUM(D24:D28) | E29: =AVERAGE('Raw Source Data'!E5:E54)
A32: Distribution of Books by Price Tier
A33: Price Tier | B33: Count (Books) | C33: Percentage (%)
A34: Low Tier (< £20.00) | B34: =COUNTIFS('Raw Source Data'!E$5:E$54, ">=0", 'Raw Source Data'!E$5:E$54, "<20") | C34: =B34/B$37
A35: Mid Tier (£20.00 - £40.00) | B35: =COUNTIFS('Raw Source Data'!E$5:E$54, ">=20", 'Raw Source Data'!E$5:E$54, "<40") | C35: =B35/B$37
A36: High Tier (> £40.00) | B36: =COUNTIFS('Raw Source Data'!E$5:E$54, ">=40", 'Raw Source Data'!E$5:E$54, "<=60") | C36: =B36/B$37
A37: Total | B37: =SUM(B34:B36) | C37: =SUM(C34:C36)
